
`double div(String a, String b) => int.parse(a) / int.parse(b);`  
  
Чтобы обрабатывать исключения, ошибки, нужно использовать try..catch:  
  
```dart
try {  
	div("5","Ноль");  
} catch(error) {  
	print(error)  
} 
``` 
  
Если в try произошла ошибка, то она передается в catch и можно с этой ошибкой что-то сделать. При этом программа не упадёт.  
При этом в catch программа попадает сразу при возникновении ошибки, дальнейший код в try игнорируется  
  
Мы можешь создавать свои исключения:  
  
```dart
class IncorrectItnString {  
	final String incorrectString;  
	IncorrectItnString(this.incorrectString);  
  
	@override  
	String toString() {  
	return "Не смогли распарсить строку в число: $incorrectString"  
	}  
};

class divisionByZero {  
	@override  
	String toString() {  
	return "На ноль делить нельзя!"  
	}  
}
  
double div(String a, String b) {  
	final aa = int.tryParse(a);  
	final bb = int.tryParse(b);  
	  
	if (aa == null) {  
	throw IncorectIntString(aa); //<-- ключевое слово throw выбрасывает исключение  
	}  
	  
	if (bb == null) {  
	throw IncorectIntString(bb); //<-- ключевое слово throw выбрасывает исключение  
	}  
	  
	if (bb == 0) {  
	throw divisionByZero(); //<-- ключевое слово throw выбрасывает исключение  
	}  
	  
	return aa/bb;  
}  
  
try {  
	div("5","Ноль");  
	} catch(error) {  
	print(error) //<- в консоли появится ошибка "Не смогли распарсить строку в число: Ноль"  
}  
  
try {  
	div("5","0");  
	} catch(error) {  
	print(error) //<- в консоли появится ошибка "На ноль делить нельзя!"  
}  
```
  
Мы можем обрабатывать какие-то конкретные ошибки:  
```dart
try {  
	div("5","0");  
} on divisionByZero catch(error) {  
	print(error) //<- мы будем обрабатывать именно деление на ноль, если строка будет не корректной, то программа будет падать  
}
```  
  
И есть третья часть try...catch...finally:  
А также всё это можно группировать:  
```dart
try {  
	// Некий метод `Открыть файл x.txt`  
	div("5","0");  
	// Некий метод `Закрыть файл x.txt`, сюда мы не попадаем, так как улетаем в catch, но закрыть то файл надо
} on divisionByZero catch(error) {  
	print(error);  
} on IncorrectItnString catch(error) {  
	print(error);  
} catch(error) {  
	print(error);  
} finally {  
	print("Деление завершено")  
	// Некий метод `Закрыть файл x.txt`, сюда мы попадаем в любом случае
}  
```
  
finally выполняется всегда, вне зависимости от исхода работы try..catch  
Таким образом, в примере выше, если мы откроем файл, а потом во время деления возникнет ошибка, в finally файл всё-таки будет закрыт  
  
```dart
class NegativeInt{  
	@override  
	String toString() {  
	return "Вы ввели число меньше 1"  
	}  
}  
  
double inSquare(double a) {  
	if (a < 1) {  
	throw NegativeInt();  
	}  
	return a * a;  
}  
```
  
Ошибки всплывают до того места, где происходит обработка. Т.е., ели вызвать функцию inSquare внутри функции div, то, если мы в inSquare передадим число <1, то всё равно увидим ошибку в try..catch